Workbook

Sheet Version
B8: معلومات الإصدار والوثيقة
B10: التصنيف الأمني: سري للاستخدام الداخلي
B11: رقم الإصدار: 1.0
B12: تاريخ الاعتماد: سبتمبر 2026
B13: الاعتماد: الإدارة التنفيذية العليا - بنك الآفاق الرقمية

Sheet ISO27001 Annex A Applicability
F7: Terms used
B8: بيان تطبيق الضوابط (Statement of Applicability - SoA) وفق المواصفة ISO/IEC 27001:2022 | F8: نظام إدارة أمن المعلومات - بنك الآفاق الرقمية
B9: ملاحظة: يتضمن هذا الجدول كافة ضوابط الملحق (Annex A) الـ 93 ومستوى تطبيقها المعتمد للبنك.
B12: المجال / القسم | C12: الضابط الرقابي (Control) | D12: هل الضابط منطبق؟ | E12: هل الضابط مطبق؟ | F12: مبرر التضمين أو الاستبعاد (Justification) | G12: ملاحظات وتفاصيل التطبيق وخطة العمل (Implementation Details)
B14: A.5 Organizational controls
C15: A.5.1 Policies for information security | D15: Yes | E15: No | F15: متطلب إلزامي لحوكمة أمن المعلومات والامتثال لإطار البنك المركزي السعودي (ساما). | G15: السياسة الحالية قديمة؛ يجري تحديثها واعتماد حزمة السياسات الجديدة لعام 2026.
C16: A.5.2 Information security roles and responsibilities | D16: Yes | E16: Yes | F16: تحديد المسؤوليات والمساءلة الإدارية والأمنية لمنع تداخل الاختصاصات. | G16: محددة رسمياً وتتضمن CISO وفرق العمليات الأمنية وإدارة تقنية المعلومات والمخاطر.
C17: A.5.3 Segregation of duties | D17: Yes | E17: Yes | F17: منع إساءة الاستخدام والاحتيال الداخلي في المعاملات البنكية والائتمانية. | G17: مطبقة بالفصل الإجرائي والتقني بين مطوري الأنظمة ومشغلي بيئة الإنتاج والصلاحيات المالية.
C18: A.5.4 Management responsibilities | D18: Yes | E18: Yes | F18: إلزام الإدارة التنفيذية بتطبيق وتوجيه سياسات أمن المعلومات ومتابعتها. | G18: يتم تطبيقها عبر المتابعة الدورية للرئيس التنفيذي ولجنة المخاطر وتقارير الأداء.
C19: A.5.5 Contact with authorities | D19: Yes | E19: Yes | F19: الالتزام بالإبلاغ الفوري عن الحوادث الجسيمة للجهات الرقابية (ساما، سدايا). | G19: قنوات تواصل معتمدة ومفعلة مع البنك المركزي وسدايا والجهات الأمنية المختصة.
C20: A.5.6 Contact with special interest groups | D20: Yes | E20: No | F20: مواكبة التهديدات السيبرانية المصرفية المستجدة وتبادل المعلومات المتخصصة. | G20: يوصى بالانضمام إلى مراكز مشاركة المعلومات المصرفية (FS-ISAC) والمنتديات الوطنية.
C21: A.5.7 Threat intelligence | D21: Yes | E21: No | F21: الرصد الاستباقي للتهديدات الموجهة للقطاع المالي (الفدية والتصيد الاحتيالي). | G21: عملية جمع وتحليل معلومات التهديدات غير منهجية حالياً؛ جاري التعاقد على منصة استخبارات تهديدات.
C22: A.5.8 Information security in project management | D22: Yes | E22: Yes | F22: ضمان تضمين متطلبات الأمان في المشاريع التقنية المصرفية مثل تطبيق آفاق بلس. | G22: تُدرج المتطلبات الأمنية في خطط مشاريع التطوير والتحول الرقمي بالبنك.
C23: A.5.9 Inventory of information and other associated assets | D23: Yes | E23: Yes | F23: حصر وتصنيف أصول المعلومات ومكونات البنية التحتية لحمايتها بفاعلية. | G23: يوجد سجل أصول تفصيلي يشمل الأصول المعلوماتية والبرمجية والمادية والأفراد.
C24: A.5.10 Acceptable use of information and other associated assets | D24: Yes | E24: No | F24: وضع قواعد واضحة للاستخدام المقبول للأجهزة والبريد ومنع السلوكيات الخطرة. | G24: توجد وثيقة عامة غير مفصلة ولا تمنع الاستخدام الشخصي ولا توجد آلية إقرار سنوي؛ جاري تحديثها.
C25: A.5.11 Return of assets | D25: Yes | E25: Yes | F25: حماية ممتلكات وأجهزة ومعلومات البنك عند انتهاء خدمة الموظفين أو تدويرهم. | G25: يتم تسليم العهد والأجهزة وبطاقات الدخول ضمن إجراءات إخلاء الطرف المعتمدة لدى الموارد البشرية.
C26: A.5.12 Classification of information | D26: Yes | E26: Yes | F26: تحديد مستوى الحماية والسرية المطلوب لكل نوع من البيانات والمعاملات. | G26: تطبيق سياسة تصنيف البيانات إلى: سري للغاية، سري، داخلي، وعام.
... C51: A.5.37 Documented operating procedures | D51: Yes | E51: No | F51: توحيد الممارسات التشغيلية ومنع الأخطاء الفردية كحذف قواعد جدار الحماية. | G51: وجود نقص في توثيق الإجراءات التشغيلية لتقنية المعلومات؛ جاري إعداد وتوثيق أدلة التشغيل القياسية.
C53: Totals: | D53: =+COUNTIF(D15:D51,"Yes") -> 37 | E53: =+COUNTIF(E15:E51,"Yes") -> 24
B55: A.6 People controls
C56: A.6.1 Screening | D56: Yes | E56: Yes | F56: التحقق من نزاهة وملاءمة الموظفين والمقاولين قبل منحهم صلاحيات الوصول. | G56: إجراء مسح أمني وفحص السجلات الجنائية والائتمانية لجميع الموظفين قبل التعيين.
C57: A.6.2 Terms and conditions of employment | D57: Yes | E57: Yes | F57: إلزام العاملين قانونياً بالحفاظ على أمن وسرية المعلومات ومسؤولياتهم الوظيفية. | G57: تضمين شروط والتزامات أمن المعلومات وسياسات العمل في كافة عقود التوظيف.
C58: A.6.3 Information security awareness, education and training | D58: Yes | E58: No | F58: رفع الوعي الأمني وخفض معدل الوقوع في هجمات التصيد الاحتيالي (كان 25%). | G58: تم إجراء اختبار محاكاة أظهر ضعف التجاوب؛ جاري إطلاق برنامج تدريبي إلزامي وحملات دورية مكثفة.
C59: A.6.4 Disciplinary process | D59: Yes | E59: Yes | F59: مساءلة ومعاقبة من ينتهك سياسات وضوابط أمن المعلومات عمداً أو إهمالاً. | G59: تطبيق لائحة الجزاءات التأديبية المعتمدة بالبنك وإجراء التحقيقات الإدارية اللازمة.
C60: A.6.5 Responsibilities after termination or change of employment | D60: Yes | E60: Yes | F60: منع تسريب البيانات واسترداد كافة العهد والأجهزة عند إنهاء أو تغيير الوظيفة. | G60: إلغاء فوري لحسابات الموظف المستقيل وسحب الأجهزة والبطاقات والتذكير بالتزامات السرية.
C61: A.6.6 Confidentiality or non-disclosure agreements | D61: Yes | E61: Yes | F61: حماية سرية البيانات المصرفية والمالية ومنع إفشائها لأطراف خارجية. | G61: توقيع اتفاقيات عدم إفصاح (NDA) إلزامية على جميع العاملين والمتعاقدين والموردين.
C62: A.6.7 Remote working | D62: Yes | E62: Yes | F62: تأمين العمل عن بُعد وحماية الاتصالات المتنقلة من الاختراق أو التنصت. | G62: استخدام أجهزة الشركة المشفرة حصراً والاتصال عبر VPN مؤمن مع مصادقة متعددة العوامل MFA.
C63: A.6.8 Information security event reporting | D63: Yes | E63: No | F63: سرعة الإبلاغ عن الأحداث والمخاوف الأمنية لتمكين المعالجة الفورية. | G63: أبلغ 8% فقط في الاختبار الأخير؛ جاري تفعيل زر الإبلاغ بنقرة واحدة في البريد وتدريب الموظفين عليه.
C65: Totals: | D65: =+COUNTIF(D56:D63,"Yes") -> 8 | E65: =+COUNTIF(E56:E63,"Yes") -> 6
B67: A.7 Physical controls
C68: A.7.1 Physical security perimeters | D68: Yes | E68: Yes | F68: حماية مبنى المقر الرئيسي والفروع من محاولات التسلل المادي غير المصرح. | G68: أسوار أمنية، بوابات مراقبة، وحراسات أمنية مشددة على مدار الساعة في كافة المواقع.
C69: A.7.2 Physical entry | D69: Yes | E69: Yes | F69: تقييد الدخول إلى المقرات ومراكز البيانات الحساسة للأشخاص المصرح لهم. | G69: بوابات إلكترونية تفتح بالبطاقات الذكية والمصادقة البيومترية وسجلات دخول رقمية للزوار.
C70: A.7.3 Securing offices, rooms and facilities | D70: Yes | E70: Yes | F70: حماية المكاتب وغرف العمليات المصرفية ومراكز التحكم (SOC) من الدخول العشوائي. | G70: أبواب مقفلة إلكترونياً، ونطاقات وصول مفصولة بحسب الصلاحيات الوظيفية في كل طابق.
C71: A.7.4 Physical security monitoring | D71: Yes | E71: Yes | F71: الرصد المستمر للمواقع والمرافق وكشف أي تحركات أو اختراقات مشبوهة. | G71: شبكة كاميرات مراقبة (CCTV) عالية الدقة تغطي كافة المداخل ومراكز البيانات وأجهزة الصراف.
C72: A.7.5 Protecting against physical and environmental threats | D72: Yes | E72: Yes | F72: حماية البنية التحتية من أخطار الحريق وارتفاع الحرارة وانقطاع الطاقة. | G72: أنظمة إخماد حريق بالغاز النظيف، أجهزة تكييف دقيقة، وعوازل بيئية في مراكز البيانات.
C73: A.7.6 Working in secure areas | D73: Yes | E73: Yes | F73: حماية أمن وسرية العمليات الحساسة داخل مركز البيانات الرئيسي والـ SOC. | G73: حظر دخول الأجهزة المحمولة غير المصرح بها والكاميرات وإلزام المرافقة الأمنية للزوار الفنيين.
C74: A.7.7 Clear desk and clear screen | D74: Yes | E74: Yes | F74: منع التلصص أو سرقة المستندات والبيانات المصرفية المتروكة على المكاتب والشاشات. | G74: تطبيق سياسة المكتب النظيف وإقفال الشاشات تلقائياً عند مغادرة الموظف لمكتبه.
C75: A.7.8 Equipment siting and protection | D75: Yes | E75: Yes | F75: حماية أجهزة الخوادم والراوترات من التلف المادي أو العبث التشغيلي. | G75: تركيب الأجهزة داخل كبائن خوادم مقفلة ومؤمنة في بيئات مخصصة ومهيأة في الفروع والمقر.
C76: A.7.9 Security of assets off-premises | D76: Yes | E76: No | F76: معالجة حادثة فقدان حاسوب مدير التسويق غير المشفر في رحلة عمل خارج المملكة. | G76: تطبيق التشفير الكامل للأقراص وسياسة أمن الأجهزة المتنقلة وحظر تخزين قواعد البيانات محلياً.
C77: A.7.10 Storage media | D77: Yes | E77: Yes | F77: حماية وسائط التخزين والأشرطة الممغنطة من السرقة أو التلف أو الوصول غير المصرح. | G77: حفظ أشرطة النسخ الاحتياطي في خزائن مصفحة ومقاومة للحريق ونقلها عبر قنوات أمنية معتمدة.
...

Sheet ISO27001 Annex A Dashboard
B8: ISO/IEC 27001 Statement of Applicability dashboard
B9: To refresh chart data, click on “Refresh All” on the Data ribbon.
B11: Statement of applicability results
B13: AREA OF STANDARD | C13: NO OF CONTROLS | D13: APPLICABLE CONTROLS | E13: % CONTROLS APPLICABLE | F13: CONTROLS IMPLEMENTED | G13: % APP CONTROLS IMPLEMENTED | I13: ISO/IEC 27001 Annex A controls percentage of controls applicable and implemented radar chart
B14: A.5 Organizational controls | C14: 37 | D14: ='ISO27001 Annex A Applicability'!D53 -> 37 | E14: =ISO27001ApplicabilityTableResults11[[#This Row],[APPLICABLE CONTROLS]]/ISO27001ApplicabilityTableResults11[[#This Row],[NO OF CONTROLS]] -> 1 | F14: ='ISO27001 Annex A Applicability'!E53 -> 24 | G14: =IF(D14=0,1,+F14/D14) -> 0.64864865
B15: A.6 People controls | C15: 8 | D15: ='ISO27001 Annex A Applicability'!D65 -> 8 | E15: =ISO27001ApplicabilityTableResults11[[#This Row],[APPLICABLE CONTROLS]]/ISO27001ApplicabilityTableResults11[[#This Row],[NO OF CONTROLS]] -> 1 | F15: ='ISO27001 Annex A Applicability'!E65 -> 6 | G15: =IF(D15=0,1,+F15/D15) -> 0.75
B16: A.7 Physical controls | C16: 14 | D16: ='ISO27001 Annex A Applicability'!D83 -> 14 | E16: =ISO27001ApplicabilityTableResults11[[#This Row],[APPLICABLE CONTROLS]]/ISO27001ApplicabilityTableResults11[[#This Row],[NO OF CONTROLS]] -> 1 | F16: ='ISO27001 Annex A Applicability'!E83 -> 12 | G16: =IF(D16=0,1,+F16/D16) -> 0.85714286
B17: A.8 Technological controls | C17: 34 | D17: ='ISO27001 Annex A Applicability'!D121 -> 34 | E17: =ISO27001ApplicabilityTableResults11[[#This Row],[APPLICABLE CONTROLS]]/ISO27001ApplicabilityTableResults11[[#This Row],[NO OF CONTROLS]] -> 1 | F17: ='ISO27001 Annex A Applicability'!E121 -> 13 | G17: =IF(D17=0,1,+F17/D17) -> 0.38235294
B18: Total | C18: =SUBTOTAL(109,ISO27001ApplicabilityTableResults11[NO OF CONTROLS]) -> 93 | D18: =SUBTOTAL(109,ISO27001ApplicabilityTableResults11[APPLICABLE CONTROLS]) -> 93 | E18: =SUBTOTAL(101,ISO27001ApplicabilityTableResults11[% CONTROLS APPLICABLE]) -> 1 | F18: =SUBTOTAL(109,ISO27001ApplicabilityTableResults11[CONTROLS IMPLEMENTED]) -> 55 | G18: =SUBTOTAL(101,ISO27001ApplicabilityTableResults11[% APP CONTROLS IMPLEMENTED]) -> 0.65953611
B22: ISO/IEC 27001 Annex A controls number of controls applicable and implemented
I38: ISO/IEC 27001 Annex A controls percentage of controls applicable and implemented

Sheet ISO27001 Applicability Table
B4: ISO/IEC 27001 Statement of Applicability results
B6: AREA OF STANDARD | C6: NO OF CONTROLS | D6: APPLICABLE CONTROLS | E6: % CONTROLS APPLICABLE | F6: CONTROLS IMPLEMENTED | G6: % APP CONTROLS IMPLEMENTED
B7: A.5 Organizational controls | C7: 37 | D7: ='ISO27001 Annex A Applicability'!D53 -> 37 | E7: =ISO27001ApplicabilityTableResults[[#This Row],[APPLICABLE CONTROLS]]/ISO27001ApplicabilityTableResults[[#This Row],[NO OF CONTROLS]] -> 1 | F7: ='ISO27001 Annex A Applicability'!E53 -> 24 | G7: =IF(D7=0,1,+F7/D7) -> 0.64864865
B8: A.6 People controls | C8: 8 | D8: ='ISO27001 Annex A Applicability'!D65 -> 8 | E8: =ISO27001ApplicabilityTableResults[[#This Row],[APPLICABLE CONTROLS]]/ISO27001ApplicabilityTableResults[[#This Row],[NO OF CONTROLS]] -> 1 | F8: ='ISO27001 Annex A Applicability'!E65 -> 6 | G8: =IF(D8=0,1,+F8/D8) -> 0.75
B9: A.7 Physical controls | C9: 14 | D9: ='ISO27001 Annex A Applicability'!D83 -> 14 | E9: =ISO27001ApplicabilityTableResults[[#This Row],[APPLICABLE CONTROLS]]/ISO27001ApplicabilityTableResults[[#This Row],[NO OF CONTROLS]] -> 1 | F9: ='ISO27001 Annex A Applicability'!E83 -> 12 | G9: =IF(D9=0,1,+F9/D9) -> 0.85714286
B10: A.8 Technological controls | C10: 34 | D10: ='ISO27001 Annex A Applicability'!D121 -> 34 | E10: =ISO27001ApplicabilityTableResults[[#This Row],[APPLICABLE CONTROLS]]/ISO27001ApplicabilityTableResults[[#This Row],[NO OF CONTROLS]] -> 1 | F10: ='ISO27001 Annex A Applicability'!E121 -> 13 | G10: =IF(D10=0,1,+F10/D10) -> 0.38235294
B11: Total | C11: =SUBTOTAL(109,ISO27001ApplicabilityTableResults[NO OF CONTROLS]) -> 93 | D11: =SUBTOTAL(109,ISO27001ApplicabilityTableResults[APPLICABLE CONTROLS]) -> 93 | E11: =SUBTOTAL(101,ISO27001ApplicabilityTableResults[% CONTROLS APPLICABLE]) -> 1 | F11: =SUBTOTAL(109,ISO27001ApplicabilityTableResults[CONTROLS IMPLEMENTED]) -> 55 | G11: =SUBTOTAL(101,ISO27001ApplicabilityTableResults[% APP CONTROLS IMPLEMENTED]) -> 0.65953611

Sheet ISO27001 Results Chart
B4: ISO/IEC 27001 Annex A Controls Number of Controls Applicable and Implemented
B6: AREA OF STANDARD | C6: APPLICABLE CONTROLS | D6: CONTROLS IMPLEMENTED
B7: A.8 Technological controls | C7: 34 | D7: 34
B8: A.7 Physical controls | C8: 14 | D8: 14
B9: A.6 People controls | C9: 8 | D9: 8
B10: A.5 Organizational controls | C10: 37 | D10: 37

Sheet ISO27001 % Results Chart
B4: ISO/IEC 27001 Annex A Controls Percentage of Controls Applicable and Implemented
B6: AREA OF STANDARD | C6: % APP CONTROLS IMPLEMENTED | D6: % CONTROLS APPLICABLE
B7: A.5 Organizational controls | C7: 1 | D7: 1
B8: A.6 People controls | C8: 1 | D8: 1
B9: A.7 Physical controls | C9: 1 | D9: 1
B10: A.8 Technological controls | C10: 1 | D10: 1

Sheet ISO27001 % Radar Chart
B4: ISO/IEC 27001 Annex A Controls Percentage of Controls Applicable and Implemented Radar Chart
B6: AREA OF STANDARD | C6: % APP CONTROLS IMPLEMENTED | D6: % CONTROLS APPLICABLE
B7: A.5 Organizational controls | C7: 1 | D7: 1
B8: A.6 People controls | C8: 1 | D8: 1
B9: A.7 Physical controls | C9: 1 | D9: 1
B10: A.8 Technological controls | C10: 1 | D10: 1
